Workbook

Sheet Summary
A1: Urea OTS stream lag — evidence and selected model
A2: Finding | B2: Value | C2: Status | D2: Basis
A3: Normal independent anchors | B3: =COUNTA('Normal Anchors'!A5:A21) -> 17 | C3: INFO | D3: 17 hourly points
A4: Startup independent anchors | B4: =COUNTA('Startup Anchors'!A5:A11) -> 7 | C4: INFO | D4: 7 hourly points
A5: Subhour timing | B5: Not identifiable | C5: LIMIT | D5: 30-second rows are synthetic linear interpolation
A6: Observed response bin | B6: 0 h | C6: SUPPORTED | D6: Feed and several Unit 322 gradients move in the same hourly bin
A7: Defensible dead-time statement | B7: <3600 s | C7: SUPPORTED | D7: One-hour independent sampling interval
A8: Selected line anchor | B8: 20 s at design liquid flow | C8: ASSUMPTION | D8: Existing reduced-order liquid-slug anchor
A9: Live route law | B9: theta = 3600 M_line / live mass flow | C9: MODEL | D9: Plug-flow effective inventory
A10: Receiver time constant | B10: tau approximately M / mass throughput | C10: MODEL | D10: Existing well-mixed vessel balances
A11: Property synchronization | B11: Whole packet | C11: REQUIRED | D11: Flow, temperature, composition, and Cp share one FIFO

Sheet Normal Anchors
A1: Normal — independent hourly anchors
A2: Only these rows are independent measurements; 30-second rows were interpolated.
A4: Timestamp | B4: UREA-LOAD | C4: HIC-322605 | D4: LV-322501 | E4: HV-322602 | F4: HIC-322604 | G4: PT-329206 | H4: PIC-329204 | I4: SIC-321951 | J4: TT-321001 | K4: FYM-322403 | L4: PT-321202 | M4: TT-321020 | N4: TT-322012 | O4: TT-322002 | P4: PT-329201 | Q4: TT-322011 | R4: TIC-329005 | S4: TDY-329125 | T4: PIC-322203 | U4: PV-322203 | V4: TT-322017 | W4: TT-322006 | X4: TT-322013 | Y4: TT-322010 | Z4: TT-322008 | AA4: TT-322007 | AB4: TT-322005 | AC4: TT-322009 | AD4: TT-322014 | AE4: AY-322701 | AF4: FY-322403 | AG4: TT-322004 | AH4: FY-329403
A5: 45837.374 | B5: 99.7 | C5: 55 | D5: 43.9 | E5: 65 | F5: 78.5 | G5: 3.99 | H5: 19.7 | I5: 121.4 | J5: 28 | K5: 52.8 | L5: 20 | M5: 29.1 | N5: 113.5 | O5: 164.1 | P5: 138.3 | Q5: 130.5 | R5: 85.2 | S5: 18.9 | T5: 144.4 | U5: 0 | V5: 113.8 | W5: 179.8 | X5: 187.1 | Y5: 169.3 | Z5: 171 | AA5: 174.3 | AB5: 183.1 | AC5: 184.6 | AD5: 183.4 | AE5: 3.23 | AF5: 28166 | AG5: 168.7 | AH5: 65.1
A6: 45837.416 | B6: 99.1 | C6: 54.5 | D6: 43.6 | E6: 65 | F6: 78.5 | G6: 3.99 | H6: 19.6 | I6: 119.8 | J6: 23.9 | K6: 52.5 | L6: 20.2 | M6: 24.9 | N6: 111.9 | O6: 164.2 | P6: 137.9 | Q6: 130.5 | R6: 85.2 | S6: 20 | T6: 144.1 | U6: 0 | V6: 114 | W6: 180 | X6: 187.1 | Y6: 169.4 | Z6: 171.3 | AA6: 174.5 | AB6: 183.2 | AC6: 184.6 | AD6: 183.4 | AE6: 3.21 | AF6: 28114 | AG6: 168.2 | AH6: 65.3
A7: 45837.458 | B7: 99.4 | C7: 54.5 | D7: 44.7 | E7: 65 | F7: 78.5 | G7: 4.02 | H7: 19.7 | I7: 122.6 | J7: 24.4 | K7: 52.7 | L7: 20.3 | M7: 25.7 | N7: 115.3 | O7: 167.1 | P7: 139.2 | Q7: 131.5 | R7: 84.2 | S7: 21.5 | T7: 144.4 | U7: 0 | V7: 114.2 | W7: 180.3 | X7: 187.1 | Y7: 169.8 | Z7: 171.8 | AA7: 175 | AB7: 183.6 | AC7: 185.1 | AD7: 183.4 | AE7: 3.19 | AF7: 28193 | AG7: 168.9 | AH7: 65.6
A8: 45837.499 | B8: 99.5 | C8: 54.5 | D8: 44.3 | E8: 66 | F8: 78 | G8: 4.04 | H8: 19.7 | I8: 124.6 | J8: 25 | K8: 52.7 | L8: 20.2 | M8: 26.3 | N8: 114.8 | O8: 166.1 | P8: 139.5 | Q8: 129.5 | R8: 85.2 | S8: 19.6 | T8: 145.2 | U8: 0 | V8: 114.7 | W8: 180.2 | X8: 187.1 | Y8: 169.9 | Z8: 171.7 | AA8: 174.8 | AB8: 183.5 | AC8: 185.1 | AD8: 183.9 | AE8: 3.21 | AF8: 28267 | AG8: 168.7 | AH8: 64.1
A9: 45837.541 | B9: 100.8 | C9: 54.7 | D9: 44.6 | E9: 66 | F9: 78 | G9: 4.04 | H9: 19.7 | I9: 122.7 | J9: 25 | K9: 53.4 | L9: 20.3 | M9: 26.3 | N9: 113.8 | O9: 165.4 | P9: 141.1 | Q9: 129 | R9: 85.2 | S9: 19.6 | T9: 145.6 | U9: 0 | V9: 115.4 | W9: 180.4 | X9: 187.6 | Y9: 170.1 | Z9: 171.8 | AA9: 174.9 | AB9: 183.7 | AC9: 185.3 | AD9: 183.9 | AE9: 3.22 | AF9: 28572 | AG9: 169.2 | AH9: 63.9
A10: 45837.583 | B10: 100.2 | C10: 55 | D10: 45.2 | E10: 66 | F10: 78 | G10: 4.04 | H10: 19.8 | I10: 123.4 | J10: 25.3 | K10: 53.1 | L10: 20.3 | M10: 26.5 | N10: 114.4 | O10: 166.1 | P10: 139.2 | Q10: 129.6 | R10: 84.3 | S10: 21.1 | T10: 145.2 | U10: 0 | V10: 115.7 | W10: 179.8 | X10: 187.6 | Y10: 170.1 | Z10: 171.9 | AA10: 174.8 | AB10: 183.5 | AC10: 185.4 | AD10: 183.9 | AE10: 3.22 | AF10: 28360 | AG10: 169.3 | AH10: 63.6
A11: 45837.624 | B11: 100.5 | C11: 55.2 | D11: 45.5 | E11: 66 | F11: 78 | G11: 4.04 | H11: 19.7 | I11: 124.2 | J11: 25 | K11: 53.3 | L11: 20.2 | M11: 26.3 | N11: 113.9 | O11: 166.1 | P11: 139 | Q11: 130.1 | R11: 84.3 | S11: 20.8 | T11: 144.8 | U11: 0 | V11: 115.4 | W11: 179.9 | X11: 187.6 | Y11: 170 | Z11: 171.5 | AA11: 174.5 | AB11: 183.2 | AC11: 185.4 | AD11: 183.9 | AE11: 3.22 | AF11: 28443 | AG11: 169.2 | AH11: 63.2
A12: 45837.666 | B12: 100.1 | C12: 55.4 | D12: 45.5 | E12: 66 | F12: 78 | G12: 4.04 | H12: 19.5 | I12: 124 | J12: 25 | K12: 53.1 | L12: 20.2 | M12: 26.3 | N12: 112.8 | O12: 165.6 | P12: 139.6 | Q12: 129.6 | R12: 85.3 | S12: 19.8 | T12: 144.7 | U12: 0 | V12: 114.9 | W12: 179.4 | X12: 187.6 | Y12: 169.8 | Z12: 170.9 | AA12: 174 | AB12: 183 | AC12: 185.3 | AD12: 183.9 | AE12: 3.24 | AF12: 28351 | AG12: 168.9 | AH12: 62.9
A13: 45837.708 | B13: 100.6 | C13: 55 | D13: 44.7 | E13: 66 | F13: 78 | G13: 4.04 | H13: 19.4 | I13: 121.8 | J13: 25 | K13: 53.3 | L13: 20.4 | M13: 26.3 | N13: 112.4 | O13: 165 | P13: 139.9 | Q13: 131 | R13: 84.3 | S13: 19.3 | T13: 145.2 | U13: 0 | V13: 114.9 | W13: 179.4 | X13: 187.6 | Y13: 169.9 | Z13: 171 | AA13: 174 | AB13: 182.8 | AC13: 185.2 | AD13: 183.4 | AE13: 3.34 | AF13: 28480 | AG13: 167.6 | AH13: 61.3
A14: 45837.749 | B14: 100.8 | C14: 55.5 | D14: 45.4 | E14: 66 | F14: 78 | G14: 4.05 | H14: 19.5 | I14: 121.9 | J14: 24.5 | K14: 53.4 | L14: 20.3 | M14: 26 | N14: 113 | O14: 166.1 | P14: 139.5 | Q14: 130.5 | R14: 83.3 | S14: 21.3 | T14: 144.8 | U14: 0 | V14: 114.5 | W14: 179.7 | X14: 187.6 | Y14: 169.9 | Z14: 171.3 | AA14: 174.3 | AB14: 183 | AC14: 185.3 | AD14: 183.4 | AE14: 3.23 | AF14: 28542 | AG14: 168.9 | AH14: 63.1
A15: 45837.791 | B15: 100.5 | C15: 55.2 | D15: 44.7 | E15: 66 | F15: 78 | G15: 4.04 | H15: 19.5 | I15: 122.3 | J15: 24.8 | K15: 53.3 | L15: 20.3 | M15: 26.3 | N15: 113 | O15: 165.6 | P15: 139.6 | Q15: 130 | R15: 84.3 | S15: 19.8 | T15: 144.8 | U15: 0 | V15: 114.2 | W15: 179.5 | X15: 187.6 | Y15: 170 | Z15: 171 | AA15: 174.2 | AB15: 182.7 | AC15: 185.2 | AD15: 183.4 | AE15: 3.23 | AF15: 28629 | AG15: 168.4 | AH15: 62.8
A16: 45837.833 | B16: 100.9 | C16: 55.5 | D16: 44.7 | E16: 66 | F16: 78 | G16: 4.04 | H16: 19.5 | I16: 122.3 | J16: 25.1 | K16: 53.5 | L16: 20.3 | M16: 26.6 | N16: 113.5 | O16: 165.6 | P16: 138.4 | Q16: 130.5 | R16: 84.3 | S16: 19.8 | T16: 144.4 | U16: 0 | V16: 113.7 | W16: 179.4 | X16: 187.6 | Y16: 169.6 | Z16: 170.7 | AA16: 174 | AB16: 182.8 | AC16: 185 | AD16: 183.4 | AE16: 3.23 | AF16: 28514 | AG16: 168.9 | AH16: 63.9
... A21: 45838.041 | B21: 100.8 | C21: 55.9 | D21: 44.5 | E21: 66 | F21: 78.5 | G21: 4.04 | H21: 19.5 | I21: 122 | J21: 24.2 | K21: 53.4 | L21: 20.4 | M21: 25.4 | N21: 111.4 | O21: 164.6 | P21: 141 | Q21: 130 | R21: 83.3 | S21: 20.6 | T21: 145.7 | U21: 0 | V21: 113.4 | W21: 179.5 | X21: 187.6 | Y21: 169.3 | Z21: 170.7 | AA21: 174 | AB21: 183 | AC21: 184.8 | AD21: 183.4 | AE21: 3.26 | AF21: 28412 | AG21: 168.8 | AH21: 64.5

Sheet Normal Gradients
A1: Normal — hourly gradients
A2: Formula: value at hour h minus value at hour h-1.
A4: Timestamp | B4: UREA-LOAD | C4: HIC-322605 | D4: LV-322501 | E4: HV-322602 | F4: HIC-322604 | G4: PT-329206 | H4: PIC-329204 | I4: SIC-321951 | J4: TT-321001 | K4: FYM-322403 | L4: PT-321202 | M4: TT-321020 | N4: TT-322012 | O4: TT-322002 | P4: PT-329201 | Q4: TT-322011 | R4: TIC-329005 | S4: TDY-329125 | T4: PIC-322203 | U4: PV-322203 | V4: TT-322017 | W4: TT-322006 | X4: TT-322013 | Y4: TT-322010 | Z4: TT-322008 | AA4: TT-322007 | AB4: TT-322005 | AC4: TT-322009 | AD4: TT-322014 | AE4: AY-322701 | AF4: FY-322403 | AG4: TT-322004 | AH4: FY-329403
A5: ='Normal Anchors'!A6 -> 45837.416 | B5: ='Normal Anchors'!B6-'Normal Anchors'!B5 -> -0.6 | C5: ='Normal Anchors'!C6-'Normal Anchors'!C5 -> -0.5 | D5: ='Normal Anchors'!D6-'Normal Anchors'!D5 -> -0.3 | E5: ='Normal Anchors'!E6-'Normal Anchors'!E5 -> 0 | F5: ='Normal Anchors'!F6-'Normal Anchors'!F5 -> 0 | G5: ='Normal Anchors'!G6-'Normal Anchors'!G5 -> 0 | H5: ='Normal Anchors'!H6-'Normal Anchors'!H5 -> -0.1 | I5: ='Normal Anchors'!I6-'Normal Anchors'!I5 -> -1.6 | ... AH5: ='Normal Anchors'!AH6-'Normal Anchors'!AH5 -> 0.2
A6: ='Normal Anchors'!A7 -> 45837.458 | B6: ='Normal Anchors'!B7-'Normal Anchors'!B6 -> 0.3 | C6: ='Normal Anchors'!C7-'Normal Anchors'!C6 -> 0 | D6: ='Normal Anchors'!D7-'Normal Anchors'!D6 -> 1.1 | E6: ='Normal Anchors'!E7-'Normal Anchors'!E6 -> 0 | F6: ='Normal Anchors'!F7-'Normal Anchors'!F6 -> 0 | G6: ='Normal Anchors'!G7-'Normal Anchors'!G6 -> 0.03 | H6: ='Normal Anchors'!H7-'Normal Anchors'!H6 -> 0.1 | I6: ='Normal Anchors'!I7-'Normal Anchors'!I6 -> 2.8 | ... AH6: ='Normal Anchors'!AH7-'Normal Anchors'!AH6 -> 0.3
A7: ='Normal Anchors'!A8 -> 45837.499 | B7: ='Normal Anchors'!B8-'Normal Anchors'!B7 -> 0.1 | C7: ='Normal Anchors'!C8-'Normal Anchors'!C7 -> 0 | D7: ='Normal Anchors'!D8-'Normal Anchors'!D7 -> -0.4 | E7: ='Normal Anchors'!E8-'Normal Anchors'!E7 -> 1 | F7: ='Normal Anchors'!F8-'Normal Anchors'!F7 -> -0.5 | G7: ='Normal Anchors'!G8-'Normal Anchors'!G7 -> 0.02 | H7: ='Normal Anchors'!H8-'Normal Anchors'!H7 -> 0 | I7: ='Normal Anchors'!I8-'Normal Anchors'!I7 -> 2 | ... AH7: ='Normal Anchors'!AH8-'Normal Anchors'!AH7 -> -1.5
A8: ='Normal Anchors'!A9 -> 45837.541 | B8: ='Normal Anchors'!B9-'Normal Anchors'!B8 -> 1.3 | C8: ='Normal Anchors'!C9-'Normal Anchors'!C8 -> 0.2 | D8: ='Normal Anchors'!D9-'Normal Anchors'!D8 -> 0.3 | E8: ='Normal Anchors'!E9-'Normal Anchors'!E8 -> 0 | F8: ='Normal Anchors'!F9-'Normal Anchors'!F8 -> 0 | G8: ='Normal Anchors'!G9-'Normal Anchors'!G8 -> 0 | H8: ='Normal Anchors'!H9-'Normal Anchors'!H8 -> 0 | I8: ='Normal Anchors'!I9-'Normal Anchors'!I8 -> -1.9 | ... AH8: ='Normal Anchors'!AH9-'Normal Anchors'!AH8 -> -0.2
A9: ='Normal Anchors'!A10 -> 45837.583 | B9: ='Normal Anchors'!B10-'Normal Anchors'!B9 -> -0.6 | C9: ='Normal Anchors'!C10-'Normal Anchors'!C9 -> 0.3 | D9: ='Normal Anchors'!D10-'Normal Anchors'!D9 -> 0.6 | E9: ='Normal Anchors'!E10-'Normal Anchors'!E9 -> 0 | F9: ='Normal Anchors'!F10-'Normal Anchors'!F9 -> 0 | G9: ='Normal Anchors'!G10-'Normal Anchors'!G9 -> 0 | H9: ='Normal Anchors'!H10-'Normal Anchors'!H9 -> 0.1 | I9: ='Normal Anchors'!I10-'Normal Anchors'!I9 -> 0.7 | ... AH9: ='Normal Anchors'!AH10-'Normal Anchors'!AH9 -> -0.3
A10: ='Normal Anchors'!A11 -> 45837.624 | B10: ='Normal Anchors'!B11-'Normal Anchors'!B10 -> 0.3 | C10: ='Normal Anchors'!C11-'Normal Anchors'!C10 -> 0.2 | D10: ='Normal Anchors'!D11-'Normal Anchors'!D10 -> 0.3 | E10: ='Normal Anchors'!E11-'Normal Anchors'!E10 -> 0 | F10: ='Normal Anchors'!F11-'Normal Anchors'!F10 -> 0 | G10: ='Normal Anchors'!G11-'Normal Anchors'!G10 -> 0 | H10: ='Normal Anchors'!H11-'Normal Anchors'!H10 -> -0.1 | I10: ='Normal Anchors'!I11-'Normal Anchors'!I10 -> 0.8 | ... AH10: ='Normal Anchors'!AH11-'Normal Anchors'!AH10 -> -0.4
A11: ='Normal Anchors'!A12 -> 45837.666 | B11: ='Normal Anchors'!B12-'Normal Anchors'!B11 -> -0.4 | C11: ='Normal Anchors'!C12-'Normal Anchors'!C11 -> 0.2 | D11: ='Normal Anchors'!D12-'Normal Anchors'!D11 -> 0 | E11: ='Normal Anchors'!E12-'Normal Anchors'!E11 -> 0 | F11: ='Normal Anchors'!F12-'Normal Anchors'!F11 -> 0 | G11: ='Normal Anchors'!G12-'Normal Anchors'!G11 -> 0 | H11: ='Normal Anchors'!H12-'Normal Anchors'!H11 -> -0.2 | I11: ='Normal Anchors'!I12-'Normal Anchors'!I11 -> -0.2 | ... AH11: ='Normal Anchors'!AH12-'Normal Anchors'!AH11 -> -0.3
A12: ='Normal Anchors'!A13 -> 45837.708 | B12: ='Normal Anchors'!B13-'Normal Anchors'!B12 -> 0.5 | C12: ='Normal Anchors'!C13-'Normal Anchors'!C12 -> -0.4 | D12: ='Normal Anchors'!D13-'Normal Anchors'!D12 -> -0.8 | E12: ='Normal Anchors'!E13-'Normal Anchors'!E12 -> 0 | F12: ='Normal Anchors'!F13-'Normal Anchors'!F12 -> 0 | G12: ='Normal Anchors'!G13-'Normal Anchors'!G12 -> 0 | H12: ='Normal Anchors'!H13-'Normal Anchors'!H12 -> -0.1 | I12: ='Normal Anchors'!I13-'Normal Anchors'!I12 -> -2.2 | ... AH12: ='Normal Anchors'!AH13-'Normal Anchors'!AH12 -> -1.6
A13: ='Normal Anchors'!A14 -> 45837.749 | B13: ='Normal Anchors'!B14-'Normal Anchors'!B13 -> 0.2 | C13: ='Normal Anchors'!C14-'Normal Anchors'!C13 -> 0.5 | D13: ='Normal Anchors'!D14-'Normal Anchors'!D13 -> 0.7 | E13: ='Normal Anchors'!E14-'Normal Anchors'!E13 -> 0 | F13: ='Normal Anchors'!F14-'Normal Anchors'!F13 -> 0 | G13: ='Normal Anchors'!G14-'Normal Anchors'!G13 -> 0.01 | H13: ='Normal Anchors'!H14-'Normal Anchors'!H13 -> 0.1 | I13: ='Normal Anchors'!I14-'Normal Anchors'!I13 -> 0.1 | ... AH13: ='Normal Anchors'!AH14-'Normal Anchors'!AH13 -> 1.8
A14: ='Normal Anchors'!A15 -> 45837.791 | B14: ='Normal Anchors'!B15-'Normal Anchors'!B14 -> -0.3 | C14: ='Normal Anchors'!C15-'Normal Anchors'!C14 -> -0.3 | D14: ='Normal Anchors'!D15-'Normal Anchors'!D14 -> -0.7 | E14: ='Normal Anchors'!E15-'Normal Anchors'!E14 -> 0 | F14: ='Normal Anchors'!F15-'Normal Anchors'!F14 -> 0 | G14: ='Normal Anchors'!G15-'Normal Anchors'!G14 -> -0.01 | H14: ='Normal Anchors'!H15-'Normal Anchors'!H14 -> 0 | I14: ='Normal Anchors'!I15-'Normal Anchors'!I14 -> 0.4 | ... AH14: ='Normal Anchors'!AH15-'Normal Anchors'!AH14 -> -0.3
A15: ='Normal Anchors'!A16 -> 45837.833 | B15: ='Normal Anchors'!B16-'Normal Anchors'!B15 -> 0.4 | C15: ='Normal Anchors'!C16-'Normal Anchors'!C15 -> 0.3 | D15: ='Normal Anchors'!D16-'Normal Anchors'!D15 -> 0 | E15: ='Normal Anchors'!E16-'Normal Anchors'!E15 -> 0 | F15: ='Normal Anchors'!F16-'Normal Anchors'!F15 -> 0 | G15: ='Normal Anchors'!G16-'Normal Anchors'!G15 -> 0 | H15: ='Normal Anchors'!H16-'Normal Anchors'!H15 -> 0 | I15: ='Normal Anchors'!I16-'Normal Anchors'!I15 -> 0 | ... AH15: ='Normal Anchors'!AH16-'Normal Anchors'!AH15 -> 1.1
A16: ='Normal Anchors'!A17 -> 45837.874 | B16: ='Normal Anchors'!B17-'Normal Anchors'!B16 -> 0.4 | C16: ='Normal Anchors'!C17-'Normal Anchors'!C16 -> 0 | D16: ='Normal Anchors'!D17-'Normal Anchors'!D16 -> 0.1 | E16: ='Normal Anchors'!E17-'Normal Anchors'!E16 -> 0 | F16: ='Normal Anchors'!F17-'Normal Anchors'!F16 -> 0 | G16: ='Normal Anchors'!G17-'Normal Anchors'!G16 -> 0 | H16: ='Normal Anchors'!H17-'Normal Anchors'!H16 -> 0 | I16: ='Normal Anchors'!I17-'Normal Anchors'!I16 -> 0.9 | ... AH16: ='Normal Anchors'!AH17-'Normal Anchors'!AH16 -> 0.6
... A20: ='Normal Anchors'!A21 -> 45838.041 | B20: ='Normal Anchors'!B21-'Normal Anchors'!B20 -> 0 | C20: ='Normal Anchors'!C21-'Normal Anchors'!C20 -> 0.2 | D20: ='Normal Anchors'!D21-'Normal Anchors'!D20 -> -0.1 | E20: ='Normal Anchors'!E21-'Normal Anchors'!E20 -> 0 | F20: ='Normal Anchors'!F21-'Normal Anchors'!F20 -> 0 | G20: ='Normal Anchors'!G21-'Normal Anchors'!G20 -> 0 | H20: ='Normal Anchors'!H21-'Normal Anchors'!H20 -> 0 | I20: ='Normal Anchors'!I21-'Normal Anchors'!I20 -> -1.1 | ... AH20: ='Normal Anchors'!AH21-'Normal Anchors'!AH20 -> -0.2

Sheet Startup Anchors
A1: Startup — independent hourly anchors
A2: Only these rows are independent measurements; 30-second rows were interpolated.
A4: Timestamp | B4: UREA-LOAD | C4: PIC-322203 | D4: PV-322203 | E4: FY-322403 | F4: TT-322017 | G4: TT-322013 | H4: FY-321401 | I4: TT-321001 | J4: SIC-321951 | K4: TT-321020 | L4: TT-322012 | M4: HV-322602 | N4: PT-329201 | O4: TT-322011 | P4: HIC-322604 | Q4: TIC-329005 | R4: TDY-329125 | S4: TV-329005 | T4: TT-322010 | U4: TT-322008 | V4: TT-322007 | W4: TT-322006 | X4: TT-322005 | Y4: TT-322009 | Z4: TT-322014 | AA4: AY-322701 | AB4: LT-322504-3 | AC4: HIC-322605 | AD4: LIC-322501 | AE4: LV-322501 | AF4: PIC-329204 | AG4: FY-329403 | AH4: HIC-329601 | AI4: PT-323201 | AJ4: PT-329251
A5: 45836.417 | B5: 0 | C5: 102.7 | D5: 64.9 | E5: 0 | F5: 101.4 | G5: 152.1 | H5: 0 | I5: 24.1 | J5: -0.2 | K5: 22.5 | L5: 110.1 | M5: 0 | N5: 3.3 | O5: 134.1 | P5: 100 | Q5: 124.6 | R5: 0.2 | S5: 24.4 | T5: 142.1 | U5: 147.3 | V5: 146.2 | W5: 147.1 | X5: 155.9 | Y5: 154.8 | Z5: 114.9 | AA5: 3.71 | AB5: 0.03 | AC5: 0 | AD5: 0.2 | AE5: 0 | AF5: 13.1 | AG5: 51.5 | AH5: 100 | AI5: 0.06 | AJ5: 21.9
A6: 45836.459 | B6: 60.7 | C6: 112.9 | D6: 35 | E6: 17501 | F6: 105.2 | G6: 185.5 | H6: 37.35 | I6: 24.2 | J6: 108 | K6: 22.3 | L6: 133.8 | M6: 40 | N6: 104.1 | O6: 147.2 | P6: 50 | Q6: 109.6 | R6: 18.5 | S6: 30.9 | T6: 164.8 | U6: 167.2 | V6: 167.8 | W6: 169.2 | X6: 174.1 | Y6: 177.9 | Z6: 99.3 | AA6: 3.77 | AB6: 9.55 | AC6: 0 | AD6: 57 | AE6: 0 | AF6: 12.8 | AG6: 35 | AH6: 100 | AI6: 1.04 | AJ6: 21.9
A7: 45836.501 | B7: 65.3 | C7: 134.5 | D7: 27 | E7: 18735 | F7: 109.7 | G7: 182.1 | H7: 37.53 | I7: 29.3 | J7: 110.1 | K7: 30.9 | L7: 115.4 | M7: 40 | N7: 130 | O7: 119.3 | P7: 60 | Q7: 105 | R7: 13.3 | S7: 30.5 | T7: 167.2 | U7: 167.4 | V7: 168.3 | W7: 171.8 | X7: 174 | Y7: 179 | Z7: 173 | AA7: 3.5 | AB7: 72.25 | AC7: 29.6 | AD7: 67 | AE7: 17.6 | AF7: 14.2 | AG7: 53.3 | AH7: 0 | AI7: 2.27 | AJ7: 21.5
A8: 45836.542 | B8: 80.8 | C8: 144.1 | D8: 19 | E8: 23013 | F8: 114.2 | G8: 186.4 | H8: 32.97 | I8: 29.7 | J8: 96.4 | K8: 31.2 | L8: 122.3 | M8: 40 | N8: 137.8 | O8: 115.9 | P8: 80 | Q8: 100.4 | R8: 14.8 | S8: 30.4 | T8: 169.9 | U8: 173.3 | V8: 175.3 | W8: 178.6 | X8: 179.6 | Y8: 182.4 | Z8: 181.1 | AA8: 3.14 | AB8: 83.66 | AC8: 39.5 | AD8: 63.7 | AE8: 37.1 | AF8: 17.4 | AG8: 68.7 | AH8: 0 | AI8: 4.75 | AJ8: 22
A9: 45836.584 | B9: 92.2 | C9: 145.3 | D9: 5 | E9: 26114 | F9: 115 | G9: 186.9 | H9: 40.47 | I9: 29 | J9: 119.7 | K9: 30.9 | L9: 132.9 | M9: 50 | N9: 139.6 | O9: 135 | P9: 85 | Q9: 90.1 | R9: 19.6 | S9: 33.3 | T9: 170.5 | U9: 173.9 | V9: 177 | W9: 181.1 | X9: 183 | Y9: 185.1 | Z9: 183.5 | AA9: 3.02 | AB9: 99.73 | AC9: 44.5 | AD9: 67.5 | AE9: 42.8 | AF9: 18 | AG9: 60.1 | AH9: 0 | AI9: 5.29 | AJ9: 21.9
A10: 45836.626 | B10: 93.9 | C10: 142.5 | D10: 0 | E10: 26595 | F10: 114.6 | G10: 186.9 | H10: 41.98 | I10: 28.8 | J10: 123.4 | K10: 30.4 | L10: 123.4 | M10: 63 | N10: 136.4 | O10: 132.3 | P10: 83 | Q10: 90 | R10: 21.4 | S10: 33.6 | T10: 170.6 | U10: 173.1 | V10: 176.6 | W10: 181.3 | X10: 183.5 | Y10: 185.5 | Z10: 184 | AA10: 3.08 | AB10: 99.94 | AC10: 46 | AD10: 61.1 | AE10: 42 | AF10: 18.4 | AG10: 55.8 | AH10: 0 | AI10: 4.19 | AJ10: 22
A11: 45836.667 | B11: 97 | C11: 141.7 | D11: 0 | E11: 27419 | F11: 113.7 | G11: 186.9 | H11: 43.47 | I11: 24.7 | J11: 126.8 | K11: 26.3 | L11: 117.1 | M11: 60 | N11: 135.7 | O11: 142.4 | P11: 80 | Q11: 88.1 | R11: 15.1 | S11: 32 | T11: 170.1 | U11: 171.7 | V11: 174.5 | W11: 179.5 | X11: 182.3 | Y11: 184.1 | Z11: 182.5 | AA11: 3.14 | AB11: 99.94 | AC11: 49 | AD11: 73.2 | AE11: 45.4 | AF11: 18.7 | AG11: 61.6 | AH11: 0 | AI11: 5.01 | AJ11: 21.9

Sheet Startup Gradients
A1: Startup — hourly gradients
A2: Formula: value at hour h minus value at hour h-1.
A4: Timestamp | B4: UREA-LOAD | C4: PIC-322203 | D4: PV-322203 | E4: FY-322403 | F4: TT-322017 | G4: TT-322013 | H4: FY-321401 | I4: TT-321001 | J4: SIC-321951 | K4: TT-321020 | L4: TT-322012 | M4: HV-322602 | N4: PT-329201 | O4: TT-322011 | P4: HIC-322604 | Q4: TIC-329005 | R4: TDY-329125 | S4: TV-329005 | T4: TT-322010 | U4: TT-322008 | V4: TT-322007 | W4: TT-322006 | X4: TT-322005 | Y4: TT-322009 | Z4: TT-322014 | AA4: AY-322701 | AB4: LT-322504-3 | AC4: HIC-322605 | AD4: LIC-322501 | AE4: LV-322501 | AF4: PIC-329204 | AG4: FY-329403 | AH4: HIC-329601 | AI4: PT-323201 | AJ4: PT-329251
A5: ='Startup Anchors'!A6 -> 45836.459 | B5: ='Startup Anchors'!B6-'Startup Anchors'!B5 -> 60.7 | C5: ='Startup Anchors'!C6-'Startup Anchors'!C5 -> 10.2 | D5: ='Startup Anchors'!D6-'Startup Anchors'!D5 -> -29.9 | E5: ='Startup Anchors'!E6-'Startup Anchors'!E5 -> 17501 | F5: ='Startup Anchors'!F6-'Startup Anchors'!F5 -> 3.8 | G5: ='Startup Anchors'!G6-'Startup Anchors'!G5 -> 33.4 | H5: ='Startup Anchors'!H6-'Startup Anchors'!H5 -> 37.35 | I5: ='Startup Anchors'!I6-'Startup Anchors'!I5 -> 0.1 | ... AJ5: ='Startup Anchors'!AJ6-'Startup Anchors'!AJ5 -> 0
A6: ='Startup Anchors'!A7 -> 45836.501 | B6: ='Startup Anchors'!B7-'Startup Anchors'!B6 -> 4.6 | C6: ='Startup Anchors'!C7-'Startup Anchors'!C6 -> 21.6 | D6: ='Startup Anchors'!D7-'Startup Anchors'!D6 -> -8 | E6: ='Startup Anchors'!E7-'Startup Anchors'!E6 -> 1234 | F6: ='Startup Anchors'!F7-'Startup Anchors'!F6 -> 4.5 | G6: ='Startup Anchors'!G7-'Startup Anchors'!G6 -> -3.4 | H6: ='Startup Anchors'!H7-'Startup Anchors'!H6 -> 0.18 | I6: ='Startup Anchors'!I7-'Startup Anchors'!I6 -> 5.1 | ... AJ6: ='Startup Anchors'!AJ7-'Startup Anchors'!AJ6 -> -0.4
A7: ='Startup Anchors'!A8 -> 45836.542 | B7: ='Startup Anchors'!B8-'Startup Anchors'!B7 -> 15.5 | C7: ='Startup Anchors'!C8-'Startup Anchors'!C7 -> 9.6 | D7: ='Startup Anchors'!D8-'Startup Anchors'!D7 -> -8 | E7: ='Startup Anchors'!E8-'Startup Anchors'!E7 -> 4278 | F7: ='Startup Anchors'!F8-'Startup Anchors'!F7 -> 4.5 | G7: ='Startup Anchors'!G8-'Startup Anchors'!G7 -> 4.3 | H7: ='Startup Anchors'!H8-'Startup Anchors'!H7 -> -4.56 | I7: ='Startup Anchors'!I8-'Startup Anchors'!I7 -> 0.4 | ... AJ7: ='Startup Anchors'!AJ8-'Startup Anchors'!AJ7 -> 0.5
A8: ='Startup Anchors'!A9 -> 45836.584 | B8: ='Startup Anchors'!B9-'Startup Anchors'!B8 -> 11.4 | C8: ='Startup Anchors'!C9-'Startup Anchors'!C8 -> 1.2 | D8: ='Startup Anchors'!D9-'Startup Anchors'!D8 -> -14 | E8: ='Startup Anchors'!E9-'Startup Anchors'!E8 -> 3101 | F8: ='Startup Anchors'!F9-'Startup Anchors'!F8 -> 0.8 | G8: ='Startup Anchors'!G9-'Startup Anchors'!G8 -> 0.5 | H8: ='Startup Anchors'!H9-'Startup Anchors'!H8 -> 7.5 | I8: ='Startup Anchors'!I9-'Startup Anchors'!I8 -> -0.7 | ... AJ8: ='Startup Anchors'!AJ9-'Startup Anchors'!AJ8 -> -0.1
A9: ='Startup Anchors'!A10 -> 45836.626 | B9: ='Startup Anchors'!B10-'Startup Anchors'!B9 -> 1.7 | C9: ='Startup Anchors'!C10-'Startup Anchors'!C9 -> -2.8 | D9: ='Startup Anchors'!D10-'Startup Anchors'!D9 -> -5 | E9: ='Startup Anchors'!E10-'Startup Anchors'!E9 -> 481 | F9: ='Startup Anchors'!F10-'Startup Anchors'!F9 -> -0.4 | G9: ='Startup Anchors'!G10-'Startup Anchors'!G9 -> 0 | H9: ='Startup Anchors'!H10-'Startup Anchors'!H9 -> 1.51 | I9: ='Startup Anchors'!I10-'Startup Anchors'!I9 -> -0.2 | ... AJ9: ='Startup Anchors'!AJ10-'Startup Anchors'!AJ9 -> 0.1
A10: ='Startup Anchors'!A11 -> 45836.667 | B10: ='Startup Anchors'!B11-'Startup Anchors'!B10 -> 3.1 | C10: ='Startup Anchors'!C11-'Startup Anchors'!C10 -> -0.8 | D10: ='Startup Anchors'!D11-'Startup Anchors'!D10 -> 0 | E10: ='Startup Anchors'!E11-'Startup Anchors'!E10 -> 824 | F10: ='Startup Anchors'!F11-'Startup Anchors'!F10 -> -0.9 | G10: ='Startup Anchors'!G11-'Startup Anchors'!G10 -> 0 | H10: ='Startup Anchors'!H11-'Startup Anchors'!H10 -> 1.49 | I10: ='Startup Anchors'!I11-'Startup Anchors'!I10 -> -4.1 | ... AJ10: ='Startup Anchors'!AJ11-'Startup Anchors'!AJ10 -> -0.1

Sheet Lag Estimates
A1: Integer-hour gradient correlation checks
A2: These checks can distinguish hourly bins only. Startup has six gradients; longer-lag fits are overfit.
A4: Dataset | B4: Response tag | C4: Independent anchors | D4: Independent gradients | E4: Lag 0 h r | F4: Lag 1 h r | G4: Lag 2 h r | H4: Lag 3 h r | I4: Interpretation
A5: Normal | B5: UREA-LOAD | C5: 17 | D5: 16 | E5: =IFERROR(CORREL('Normal Gradients'!B5:B20,'Normal Gradients'!B5:B20),"") -> 1 | F5: =IFERROR(CORREL('Normal Gradients'!B5:B19,'Normal Gradients'!B6:B20),"") -> -0.51305665 | G5: =IFERROR(CORREL('Normal Gradients'!B5:B18,'Normal Gradients'!B7:B20),"") -> 0.14828821 | H5: =IFERROR(CORREL('Normal Gradients'!B5:B17,'Normal Gradients'!B8:B20),"") -> -0.26159456 | I5: =IF(OR(D5<7,COUNT(E5:H5)<4),"INSUFFICIENT",IF(ABS(E5)>=MAX(ABS(F5),ABS(G5),ABS(H5)),"0 h bin","ambiguous")) -> 0 h bin
A6: Normal | B6: HIC-322605 | C6: 17 | D6: 16 | E6: =IFERROR(CORREL('Normal Gradients'!B5:B20,'Normal Gradients'!C5:C20),"") -> 0.20784498 | F6: =IFERROR(CORREL('Normal Gradients'!B5:B19,'Normal Gradients'!C6:C20),"") -> 0.25591502 | G6: =IFERROR(CORREL('Normal Gradients'!B5:B18,'Normal Gradients'!C7:C20),"") -> -0.15028292 | H6: =IFERROR(CORREL('Normal Gradients'!B5:B17,'Normal Gradients'!C8:C20),"") -> 0.43885453 | I6: =IF(OR(D6<7,COUNT(E6:H6)<4),"INSUFFICIENT",IF(ABS(E6)>=MAX(ABS(F6),ABS(G6),ABS(H6)),"0 h bin","ambiguous")) -> ambiguous
A7: Normal | B7: LV-322501 | C7: 17 | D7: 16 | E7: =IFERROR(CORREL('Normal Gradients'!B5:B20,'Normal Gradients'!D5:D20),"") -> 0.16668863 | F7: =IFERROR(CORREL('Normal Gradients'!B5:B19,'Normal Gradients'!D6:D20),"") -> 0.132807 | G7: =IFERROR(CORREL('Normal Gradients'!B5:B18,'Normal Gradients'!D7:D20),"") -> -0.17876692 | H7: =IFERROR(CORREL('Normal Gradients'!B5:B17,'Normal Gradients'!D8:D20),"") -> 0.39078849 | I7: =IF(OR(D7<7,COUNT(E7:H7)<4),"INSUFFICIENT",IF(ABS(E7)>=MAX(ABS(F7),ABS(G7),ABS(H7)),"0 h bin","ambiguous")) -> ambiguous
A8: Normal | B8: HV-322602 | C8: 17 | D8: 16 | E8: =IFERROR(CORREL('Normal Gradients'!B5:B20,'Normal Gradients'!E5:E20),"") -> 0.015759076 | F8: =IFERROR(CORREL('Normal Gradients'!B5:B19,'Normal Gradients'!E6:E20),"") -> 0.11462961 | G8: =IFERROR(CORREL('Normal Gradients'!B5:B18,'Normal Gradients'!E7:E20),"") -> -0.34901016 | H8: =IFERROR(CORREL('Normal Gradients'!B5:B17,'Normal Gradients'!E8:E20),"") | I8: =IF(OR(D8<7,COUNT(E8:H8)<4),"INSUFFICIENT",IF(ABS(E8)>=MAX(ABS(F8),ABS(G8),ABS(H8)),"0 h bin","ambiguous")) -> INSUFFICIENT
A9: Normal | B9: HIC-322604 | C9: 17 | D9: 16 | E9: =IFERROR(CORREL('Normal Gradients'!B5:B20,'Normal Gradients'!F5:F20),"") -> -0.31073765 | F9: =IFERROR(CORREL('Normal Gradients'!B5:B19,'Normal Gradients'!F6:F20),"") -> 0.034547175 | G9: =IFERROR(CORREL('Normal Gradients'!B5:B18,'Normal Gradients'!F7:F20),"") -> 0.34680674 | H9: =IFERROR(CORREL('Normal Gradients'!B5:B17,'Normal Gradients'!F8:F20),"") -> -0.1869678 | I9: =IF(OR(D9<7,COUNT(E9:H9)<4),"INSUFFICIENT",IF(ABS(E9)>=MAX(ABS(F9),ABS(G9),ABS(H9)),"0 h bin","ambiguous")) -> ambiguous
A10: Normal | B10: PT-329206 | C10: 17 | D10: 16 | E10: =IFERROR(CORREL('Normal Gradients'!B5:B20,'Normal Gradients'!G5:G20),"") -> 0.16733362 | F10: =IFERROR(CORREL('Normal Gradients'!B5:B19,'Normal Gradients'!G6:G20),"") -> -0.1694808 | G10: =IFERROR(CORREL('Normal Gradients'!B5:B18,'Normal Gradients'!G7:G20),"") -> -0.46603725 | H10: =IFERROR(CORREL('Normal Gradients'!B5:B17,'Normal Gradients'!G8:G20),"") -> 0.24593157 | I10: =IF(OR(D10<7,COUNT(E10:H10)<4),"INSUFFICIENT",IF(ABS(E10)>=MAX(ABS(F10),ABS(G10),ABS(H10)),"0 h bin","ambiguous")) -> ambiguous
A11: Normal | B11: PIC-329204 | C11: 17 | D11: 16 | E11: =IFERROR(CORREL('Normal Gradients'!B5:B20,'Normal Gradients'!H5:H20),"") -> 0.099688315 | F11: =IFERROR(CORREL('Normal Gradients'!B5:B19,'Normal Gradients'!H6:H20),"") -> 0.27352891 | G11: =IFERROR(CORREL('Normal Gradients'!B5:B18,'Normal Gradients'!H7:H20),"") -> -0.09333797 | H11: =IFERROR(CORREL('Normal Gradients'!B5:B17,'Normal Gradients'!H8:H20),"") -> -0.24666788 | I11: =IF(OR(D11<7,COUNT(E11:H11)<4),"INSUFFICIENT",IF(ABS(E11)>=MAX(ABS(F11),ABS(G11),ABS(H11)),"0 h bin","ambiguous")) -> ambiguous
A12: Normal | B12: SIC-321951 | C12: 17 | D12: 16 | E12: =IFERROR(CORREL('Normal Gradients'!B5:B20,'Normal Gradients'!I5:I20),"") -> -0.18663267 | F12: =IFERROR(CORREL('Normal Gradients'!B5:B19,'Normal Gradients'!I6:I20),"") -> 0.098140072 | G12: =IFERROR(CORREL('Normal Gradients'!B5:B18,'Normal Gradients'!I7:I20),"") -> -0.21189181 | H12: =IFERROR(CORREL('Normal Gradients'!B5:B17,'Normal Gradients'!I8:I20),"") -> 0.47353918 | I12: =IF(OR(D12<7,COUNT(E12:H12)<4),"INSUFFICIENT",IF(ABS(E12)>=MAX(ABS(F12),ABS(G12),ABS(H12)),"0 h bin","ambiguous")) -> ambiguous
A13: Normal | B13: TT-321001 | C13: 17 | D13: 16 | E13: =IFERROR(CORREL('Normal Gradients'!B5:B20,'Normal Gradients'!J5:J20),"") -> 0.23420464 | F13: =IFERROR(CORREL('Normal Gradients'!B5:B19,'Normal Gradients'!J6:J20),"") -> 0.053248674 | G13: =IFERROR(CORREL('Normal Gradients'!B5:B18,'Normal Gradients'!J7:J20),"") -> 0.049342666 | H13: =IFERROR(CORREL('Normal Gradients'!B5:B17,'Normal Gradients'!J8:J20),"") -> -0.20979779 | I13: =IF(OR(D13<7,COUNT(E13:H13)<4),"INSUFFICIENT",IF(ABS(E13)>=MAX(ABS(F13),ABS(G13),ABS(H13)),"0 h bin","ambiguous")) -> 0 h bin
A14: Normal | B14: FYM-322403 | C14: 17 | D14: 16 | E14: =IFERROR(CORREL('Normal Gradients'!B5:B20,'Normal Gradients'!K5:K20),"") -> 0.99249538 | F14: =IFERROR(CORREL('Normal Gradients'!B5:B19,'Normal Gradients'!K6:K20),"") -> -0.52675679 | G14: =IFERROR(CORREL('Normal Gradients'!B5:B18,'Normal Gradients'!K7:K20),"") -> 0.22351812 | H14: =IFERROR(CORREL('Normal Gradients'!B5:B17,'Normal Gradients'!K8:K20),"") -> -0.27364703 | I14: =IF(OR(D14<7,COUNT(E14:H14)<4),"INSUFFICIENT",IF(ABS(E14)>=MAX(ABS(F14),ABS(G14),ABS(H14)),"0 h bin","ambiguous")) -> 0 h bin
A15: Normal | B15: PT-321202 | C15: 17 | D15: 16 | E15: =IFERROR(CORREL('Normal Gradients'!B5:B20,'Normal Gradients'!L5:L20),"") -> 0.028366337 | F15: =IFERROR(CORREL('Normal Gradients'!B5:B19,'Normal Gradients'!L6:L20),"") -> -0.34897285 | G15: =IFERROR(CORREL('Normal Gradients'!B5:B18,'Normal Gradients'!L7:L20),"") -> 0.31367832 | H15: =IFERROR(CORREL('Normal Gradients'!B5:B17,'Normal Gradients'!L8:L20),"") -> -0.41862839 | I15: =IF(OR(D15<7,COUNT(E15:H15)<4),"INSUFFICIENT",IF(ABS(E15)>=MAX(ABS(F15),ABS(G15),ABS(H15)),"0 h bin","ambiguous")) -> ambiguous
A16: Normal | B16: TT-321020 | C16: 17 | D16: 16 | E16: =IFERROR(CORREL('Normal Gradients'!B5:B20,'Normal Gradients'!M5:M20),"") -> 0.28636122 | F16: =IFERROR(CORREL('Normal Gradients'!B5:B19,'Normal Gradients'!M6:M20),"") -> -0.09161983 | G16: =IFERROR(CORREL('Normal Gradients'!B5:B18,'Normal Gradients'!M7:M20),"") -> 0.024503816 | H16: =IFERROR(CORREL('Normal Gradients'!B5:B17,'Normal Gradients'!M8:M20),"") -> -0.17728251 | I16: =IF(OR(D16<7,COUNT(E16:H16)<4),"INSUFFICIENT",IF(ABS(E16)>=MAX(ABS(F16),ABS(G16),ABS(H16)),"0 h bin","ambiguous")) -> 0 h bin
A17: Normal | B17: TT-322012 | C17: 17 | D17: 16 | E17: =IFERROR(CORREL('Normal Gradients'!B5:B20,'Normal Gradients'!N5:N20),"") -> 0.10180521 | F17: =IFERROR(CORREL('Normal Gradients'!B5:B19,'Normal Gradients'!N6:N20),"") -> -0.12784378 | G17: =IFERROR(CORREL('Normal Gradients'!B5:B18,'Normal Gradients'!N7:N20),"") -> -0.10346223 | H17: =IFERROR(CORREL('Normal Gradients'!B5:B17,'Normal Gradients'!N8:N20),"") -> 0.11150158 | I17: =IF(OR(D17<7,COUNT(E17:H17)<4),"INSUFFICIENT",IF(ABS(E17)>=MAX(ABS(F17),ABS(G17),ABS(H17)),"0 h bin","ambiguous")) -> ambiguous
A18: Normal | B18: TT-322002 | C18: 17 | D18: 16 | E18: =IFERROR(CORREL('Normal Gradients'!B5:B20,'Normal Gradients'!O5:O20),"") -> 0.027225844 | F18: =IFERROR(CORREL('Normal Gradients'!B5:B19,'Normal Gradients'!O6:O20),"") -> 0.0013478618 | G18: =IFERROR(CORREL('Normal Gradients'!B5:B18,'Normal Gradients'!O7:O20),"") -> -0.19767204 | H18: =IFERROR(CORREL('Normal Gradients'!B5:B17,'Normal Gradients'!O8:O20),"") -> 0.40975297 | I18: =IF(OR(D18<7,COUNT(E18:H18)<4),"INSUFFICIENT",IF(ABS(E18)>=MAX(ABS(F18),ABS(G18),ABS(H18)),"0 h bin","ambiguous")) -> ambiguous
A19: Normal | B19: PT-329201 | C19: 17 | D19: 16 | E19: =IFERROR(CORREL('Normal Gradients'!B5:B20,'Normal Gradients'!P5:P20),"") -> 0.46913857 | F19: =IFERROR(CORREL('Normal Gradients'!B5:B19,'Normal Gradients'!P6:P20),"") -> -0.31992295 | G19: =IFERROR(CORREL('Normal Gradients'!B5:B18,'Normal Gradients'!P7:P20),"") -> -0.1280383 | H19: =IFERROR(CORREL('Normal Gradients'!B5:B17,'Normal Gradients'!P8:P20),"") -> -0.26645174 | I19: =IF(OR(D19<7,COUNT(E19:H19)<4),"INSUFFICIENT",IF(ABS(E19)>=MAX(ABS(F19),ABS(G19),ABS(H19)),"0 h bin","ambiguous")) -> 0 h bin
A20: Normal | B20: TT-322011 | C20: 17 | D20: 16 | E20: =IFERROR(CORREL('Normal Gradients'!B5:B20,'Normal Gradients'!Q5:Q20),"") -> 0.11154556 | F20: =IFERROR(CORREL('Normal Gradients'!B5:B19,'Normal Gradients'!Q6:Q20),"") -> -0.33026475 | G20: =IFERROR(CORREL('Normal Gradients'!B5:B18,'Normal Gradients'!Q7:Q20),"") -> 0.54365276 | H20: =IFERROR(CORREL('Normal Gradients'!B5:B17,'Normal Gradients'!Q8:Q20),"") -> -0.21904079 | I20: =IF(OR(D20<7,COUNT(E20:H20)<4),"INSUFFICIENT",IF(ABS(E20)>=MAX(ABS(F20),ABS(G20),ABS(H20)),"0 h bin","ambiguous")) -> ambiguous
A21: Normal | B21: TIC-329005 | C21: 17 | D21: 16 | E21: =IFERROR(CORREL('Normal Gradients'!B5:B20,'Normal Gradients'!R5:R20),"") -> -0.16477733 | F21: =IFERROR(CORREL('Normal Gradients'!B5:B19,'Normal Gradients'!R6:R20),"") -> 0.065586919 | G21: =IFERROR(CORREL('Normal Gradients'!B5:B18,'Normal Gradients'!R7:R20),"") -> -0.19117448 | H21: =IFERROR(CORREL('Normal Gradients'!B5:B17,'Normal Gradients'!R8:R20),"") -> 0.39014576 | I21: =IF(OR(D21<7,COUNT(E21:H21)<4),"INSUFFICIENT",IF(ABS(E21)>=MAX(ABS(F21),ABS(G21),ABS(H21)),"0 h bin","ambiguous")) -> ambiguous
A22: Normal | B22: TDY-329125 | C22: 17 | D22: 16 | E22: =IFERROR(CORREL('Normal Gradients'!B5:B20,'Normal Gradients'!S5:S20),"") -> 0.00035995641 | F22: =IFERROR(CORREL('Normal Gradients'!B5:B19,'Normal Gradients'!S6:S20),"") -> 0.14326035 | G22: =IFERROR(CORREL('Normal Gradients'!B5:B18,'Normal Gradients'!S7:S20),"") -> -0.026009911 | H22: =IFERROR(CORREL('Normal Gradients'!B5:B17,'Normal Gradients'!S8:S20),"") -> 0.01025465 | I22: =IF(OR(D22<7,COUNT(E22:H22)<4),"INSUFFICIENT",IF(ABS(E22)>=MAX(ABS(F22),ABS(G22),ABS(H22)),"0 h bin","ambiguous")) -> ambiguous
A23: Normal | B23: PIC-322203 | C23: 17 | D23: 16 | E23: =IFERROR(CORREL('Normal Gradients'!B5:B20,'Normal Gradients'!T5:T20),"") -> 0.27240073 | F23: =IFERROR(CORREL('Normal Gradients'!B5:B19,'Normal Gradients'!T6:T20),"") -> -0.23666412 | G23: =IFERROR(CORREL('Normal Gradients'!B5:B18,'Normal Gradients'!T7:T20),"") -> -0.0066882126 | H23: =IFERROR(CORREL('Normal Gradients'!B5:B17,'Normal Gradients'!T8:T20),"") -> -0.56166641 | I23: =IF(OR(D23<7,COUNT(E23:H23)<4),"INSUFFICIENT",IF(ABS(E23)>=MAX(ABS(F23),ABS(G23),ABS(H23)),"0 h bin","ambiguous")) -> ambiguous
A24: Normal | B24: PV-322203 | C24: 17 | D24: 16 | E24: =IFERROR(CORREL('Normal Gradients'!B5:B20,'Normal Gradients'!U5:U20),"") | F24: =IFERROR(CORREL('Normal Gradients'!B5:B19,'Normal Gradients'!U6:U20),"") | G24: =IFERROR(CORREL('Normal Gradients'!B5:B18,'Normal Gradients'!U7:U20),"") | H24: =IFERROR(CORREL('Normal Gradients'!B5:B17,'Normal Gradients'!U8:U20),"") | I24: =IF(OR(D24<7,COUNT(E24:H24)<4),"INSUFFICIENT",IF(ABS(E24)>=MAX(ABS(F24),ABS(G24),ABS(H24)),"0 h bin","ambiguous")) -> INSUFFICIENT
A25: Normal | B25: TT-322017 | C25: 17 | D25: 16 | E25: =IFERROR(CORREL('Normal Gradients'!B5:B20,'Normal Gradients'!V5:V20),"") -> 0.35762028 | F25: =IFERROR(CORREL('Normal Gradients'!B5:B19,'Normal Gradients'!V6:V20),"") -> 0.13697533 | G25: =IFERROR(CORREL('Normal Gradients'!B5:B18,'Normal Gradients'!V7:V20),"") -> -0.17529985 | H25: =IFERROR(CORREL('Normal Gradients'!B5:B17,'Normal Gradients'!V8:V20),"") -> -0.37574068 | I25: =IF(OR(D25<7,COUNT(E25:H25)<4),"INSUFFICIENT",IF(ABS(E25)>=MAX(ABS(F25),ABS(G25),ABS(H25)),"0 h bin","ambiguous")) -> ambiguous
A26: Normal | B26: TT-322006 | C26: 17 | D26: 16 | E26: =IFERROR(CORREL('Normal Gradients'!B5:B20,'Normal Gradients'!W5:W20),"") -> 0.58803098 | F26: =IFERROR(CORREL('Normal Gradients'!B5:B19,'Normal Gradients'!W6:W20),"") -> -0.66239242 | G26: =IFERROR(CORREL('Normal Gradients'!B5:B18,'Normal Gradients'!W7:W20),"") -> 0.17462164 | H26: =IFERROR(CORREL('Normal Gradients'!B5:B17,'Normal Gradients'!W8:W20),"") -> -0.26020893 | I26: =IF(OR(D26<7,COUNT(E26:H26)<4),"INSUFFICIENT",IF(ABS(E26)>=MAX(ABS(F26),ABS(G26),ABS(H26)),"0 h bin","ambiguous")) -> ambiguous
A27: Normal | B27: TT-322013 | C27: 17 | D27: 16 | E27: =IFERROR(CORREL('Normal Gradients'!B5:B20,'Normal Gradients'!X5:X20),"") -> 0.6209076 | F27: =IFERROR(CORREL('Normal Gradients'!B5:B19,'Normal Gradients'!X6:X20),"") -> 0.013485836 | G27: =IFERROR(CORREL('Normal Gradients'!B5:B18,'Normal Gradients'!X7:X20),"") -> 0.10906567 | H27: =IFERROR(CORREL('Normal Gradients'!B5:B17,'Normal Gradients'!X8:X20),"") -> -0.34211129 | I27: =IF(OR(D27<7,COUNT(E27:H27)<4),"INSUFFICIENT",IF(ABS(E27)>=MAX(ABS(F27),ABS(G27),ABS(H27)),"0 h bin","ambiguous")) -> 0 h bin
A28: Normal | B28: TT-322010 | C28: 17 | D28: 16 | E28: =IFERROR(CORREL('Normal Gradients'!B5:B20,'Normal Gradients'!Y5:Y20),"") -> 0.11738978 | F28: =IFERROR(CORREL('Normal Gradients'!B5:B19,'Normal Gradients'!Y6:Y20),"") -> -0.14154922 | G28: =IFERROR(CORREL('Normal Gradients'!B5:B18,'Normal Gradients'!Y7:Y20),"") -> 0.15174457 | H28: =IFERROR(CORREL('Normal Gradients'!B5:B17,'Normal Gradients'!Y8:Y20),"") -> -0.67369089 | I28: =IF(OR(D28<7,COUNT(E28:H28)<4),"INSUFFICIENT",IF(ABS(E28)>=MAX(ABS(F28),ABS(G28),ABS(H28)),"0 h bin","ambiguous")) -> ambiguous
A29: Normal | B29: TT-322008 | C29: 17 | D29: 16 | E29: =IFERROR(CORREL('Normal Gradients'!B5:B20,'Normal Gradients'!Z5:Z20),"") -> 0.18410449 | F29: =IFERROR(CORREL('Normal Gradients'!B5:B19,'Normal Gradients'!Z6:Z20),"") -> -0.060757635 | G29: =IFERROR(CORREL('Normal Gradients'!B5:B18,'Normal Gradients'!Z7:Z20),"") -> -0.227344 | H29: =IFERROR(CORREL('Normal Gradients'!B5:B17,'Normal Gradients'!Z8:Z20),"") -> -0.26883765 | I29: =IF(OR(D29<7,COUNT(E29:H29)<4),"INSUFFICIENT",IF(ABS(E29)>=MAX(ABS(F29),ABS(G29),ABS(H29)),"0 h bin","ambiguous")) -> ambiguous
A30: Normal | B30: TT-322007 | C30: 17 | D30: 16 | E30: =IFERROR(CORREL('Normal Gradients'!B5:B20,'Normal Gradients'!AA5:AA20),"") -> 0.23916391 | F30: =IFERROR(CORREL('Normal Gradients'!B5:B19,'Normal Gradients'!AA6:AA20),"") -> -0.24797718 | G30: =IFERROR(CORREL('Normal Gradients'!B5:B18,'Normal Gradients'!AA7:AA20),"") -> -0.0028911718 | H30: =IFERROR(CORREL('Normal Gradients'!B5:B17,'Normal Gradients'!AA8:AA20),"") -> -0.41766354 | I30: =IF(OR(D30<7,COUNT(E30:H30)<4),"INSUFFICIENT",IF(ABS(E30)>=MAX(ABS(F30),ABS(G30),ABS(H30)),"0 h bin","ambiguous")) -> ambiguous
A31: Normal | B31: TT-322005 | C31: 17 | D31: 16 | E31: =IFERROR(CORREL('Normal Gradients'!B5:B20,'Normal Gradients'!AB5:AB20),"") -> 0.47970751 | F31: =IFERROR(CORREL('Normal Gradients'!B5:B19,'Normal Gradients'!AB6:AB20),"") -> -0.41536157 | G31: =IFERROR(CORREL('Normal Gradients'!B5:B18,'Normal Gradients'!AB7:AB20),"") -> -0.17906976 | H31: =IFERROR(CORREL('Normal Gradients'!B5:B17,'Normal Gradients'!AB8:AB20),"") -> 0.11832162 | I31: =IF(OR(D31<7,COUNT(E31:H31)<4),"INSUFFICIENT",IF(ABS(E31)>=MAX(ABS(F31),ABS(G31),ABS(H31)),"0 h bin","ambiguous")) -> 0 h bin
A32: Normal | B32: TT-322009 | C32: 17 | D32: 16 | E32: =IFERROR(CORREL('Normal Gradients'!B5:B20,'Normal Gradients'!AC5:AC20),"") -> 0.29138978 | F32: =IFERROR(CORREL('Normal Gradients'!B5:B19,'Normal Gradients'!AC6:AC20),"") -> -0.073374833 | G32: =IFERROR(CORREL('Normal Gradients'!B5:B18,'Normal Gradients'!AC7:AC20),"") -> -0.10909943 | H32: =IFERROR(CORREL('Normal Gradients'!B5:B17,'Normal Gradients'!AC8:AC20),"") -> -0.080833817 | I32: =IF(OR(D32<7,COUNT(E32:H32)<4),"INSUFFICIENT",IF(ABS(E32)>=MAX(ABS(F32),ABS(G32),ABS(H32)),"0 h bin","ambiguous")) -> 0 h bin
A33: Normal | B33: TT-322014 | C33: 17 | D33: 16 | E33: =IFERROR(CORREL('Normal Gradients'!B5:B20,'Normal Gradients'!AD5:AD20),"") -> -0.13810562 | F33: =IFERROR(CORREL('Normal Gradients'!B5:B19,'Normal Gradients'!AD6:AD20),"") -> 0.24183023 | G33: =IFERROR(CORREL('Normal Gradients'!B5:B18,'Normal Gradients'!AD7:AD20),"") -> -0.31212606 | H33: =IFERROR(CORREL('Normal Gradients'!B5:B17,'Normal Gradients'!AD8:AD20),"") -> 0.34211129 | I33: =IF(OR(D33<7,COUNT(E33:H33)<4),"INSUFFICIENT",IF(ABS(E33)>=MAX(ABS(F33),ABS(G33),ABS(H33)),"0 h bin","ambiguous")) -> ambiguous
A34: Normal | B34: AY-322701 | C34: 17 | D34: 16 | E34: =IFERROR(CORREL('Normal Gradients'!B5:B20,'Normal Gradients'!AE5:AE20),"") -> 0.11001632 | F34: =IFERROR(CORREL('Normal Gradients'!B5:B19,'Normal Gradients'!AE6:AE20),"") -> -0.21232179 | G34: =IFERROR(CORREL('Normal Gradients'!B5:B18,'Normal Gradients'!AE7:AE20),"") -> 0.16835054 | H34: =IFERROR(CORREL('Normal Gradients'!B5:B17,'Normal Gradients'!AE8:AE20),"") -> -0.28051528 | I34: =IF(OR(D34<7,COUNT(E34:H34)<4),"INSUFFICIENT",IF(ABS(E34)>=MAX(ABS(F34),ABS(G34),ABS(H34)),"0 h bin","ambiguous")) -> ambiguous
A35: Normal | B35: FY-322403 | C35: 17 | D35: 16 | E35: =IFERROR(CORREL('Normal Gradients'!B5:B20,'Normal Gradients'!AF5:AF20),"") -> 0.79842284 | F35: =IFERROR(CORREL('Normal Gradients'!B5:B19,'Normal Gradients'!AF6:AF20),"") -> -0.5514916 | G35: =IFERROR(CORREL('Normal Gradients'!B5:B18,'Normal Gradients'!AF7:AF20),"") -> 0.27905451 | H35: =IFERROR(CORREL('Normal Gradients'!B5:B17,'Normal Gradients'!AF8:AF20),"") -> -0.40558737 | I35: =IF(OR(D35<7,COUNT(E35:H35)<4),"INSUFFICIENT",IF(ABS(E35)>=MAX(ABS(F35),ABS(G35),ABS(H35)),"0 h bin","ambiguous")) -> 0 h bin
A36: Normal | B36: TT-322004 | C36: 17 | D36: 16 | E36: =IFERROR(CORREL('Normal Gradients'!B5:B20,'Normal Gradients'!AG5:AG20),"") -> 0.29364704 | F36: =IFERROR(CORREL('Normal Gradients'!B5:B19,'Normal Gradients'!AG6:AG20),"") -> 0.042756766 | G36: =IFERROR(CORREL('Normal Gradients'!B5:B18,'Normal Gradients'!AG7:AG20),"") -> -0.19808436 | H36: =IFERROR(CORREL('Normal Gradients'!B5:B17,'Normal Gradients'!AG8:AG20),"") -> 0.2980554 | I36: =IF(OR(D36<7,COUNT(E36:H36)<4),"INSUFFICIENT",IF(ABS(E36)>=MAX(ABS(F36),ABS(G36),ABS(H36)),"0 h bin","ambiguous")) -> ambiguous
A37: Normal | B37: FY-329403 | C37: 17 | D37: 16 | E37: =IFERROR(CORREL('Normal Gradients'!B5:B20,'Normal Gradients'!AH5:AH20),"") -> 0.078256591 | F37: =IFERROR(CORREL('Normal Gradients'!B5:B19,'Normal Gradients'!AH6:AH20),"") -> 0.044994712 | G37: =IFERROR(CORREL('Normal Gradients'!B5:B18,'Normal Gradients'!AH7:AH20),"") -> -0.16829533 | H37: =IFERROR(CORREL('Normal Gradients'!B5:B17,'Normal Gradients'!AH8:AH20),"") -> 0.41369391 | I37: =IF(OR(D37<7,COUNT(E37:H37)<4),"INSUFFICIENT",IF(ABS(E37)>=MAX(ABS(F37),ABS(G37),ABS(H37)),"0 h bin","ambiguous")) -> ambiguous
A38: Startup | B38: UREA-LOAD | C38: 7 | D38: 6 | E38: =IFERROR(CORREL('Startup Gradients'!B5:B10,'Startup Gradients'!B5:B10),"") -> 1 | F38: =IFERROR(CORREL('Startup Gradients'!B5:B9,'Startup Gradients'!B6:B10),"") -> -0.22779235 | G38: =IFERROR(CORREL('Startup Gradients'!B5:B8,'Startup Gradients'!B7:B10),"") -> 0.64033663 | H38: =IFERROR(CORREL('Startup Gradients'!B5:B7,'Startup Gradients'!B8:B10),"") -> 0.99873281 | I38: =IF(OR(D38<7,COUNT(E38:H38)<4),"INSUFFICIENT",IF(ABS(E38)>=MAX(ABS(F38),ABS(G38),ABS(H38)),"0 h bin","ambiguous")) -> INSUFFICIENT
A39: Startup | B39: PIC-322203 | C39: 7 | D39: 6 | E39: =IFERROR(CORREL('Startup Gradients'!B5:B10,'Startup Gradients'!C5:C10),"") -> 0.23665615 | F39: =IFERROR(CORREL('Startup Gradients'!B5:B9,'Startup Gradients'!C6:C10),"") -> 0.82817746 | G39: =IFERROR(CORREL('Startup Gradients'!B5:B8,'Startup Gradients'!C7:C10),"") -> 0.88683467 | H39: =IFERROR(CORREL('Startup Gradients'!B5:B7,'Startup Gradients'!C8:C10),"") -> 0.9429739 | I39: =IF(OR(D39<7,COUNT(E39:H39)<4),"INSUFFICIENT",IF(ABS(E39)>=MAX(ABS(F39),ABS(G39),ABS(H39)),"0 h bin","ambiguous")) -> INSUFFICIENT
A40: Startup | B40: PV-322203 | C40: 7 | D40: 6 | E40: =IFERROR(CORREL('Startup Gradients'!B5:B10,'Startup Gradients'!D5:D10),"") -> -0.93743643 | F40: =IFERROR(CORREL('Startup Gradients'!B5:B9,'Startup Gradients'!D6:D10),"") -> -0.28346933 | G40: =IFERROR(CORREL('Startup Gradients'!B5:B8,'Startup Gradients'!D7:D10),"") -> -0.011503411 | H40: =IFERROR(CORREL('Startup Gradients'!B5:B7,'Startup Gradients'!D8:D10),"") -> -0.85545341 | I40: =IF(OR(D40<7,COUNT(E40:H40)<4),"INSUFFICIENT",IF(ABS(E40)>=MAX(ABS(F40),ABS(G40),ABS(H40)),"0 h bin","ambiguous")) -> INSUFFICIENT
A41: Startup | B41: FY-322403 | C41: 7 | D41: 6 | E41: =IFERROR(CORREL('Startup Gradients'!B5:B10,'Startup Gradients'!E5:E10),"") -> 0.99992773 | F41: =IFERROR(CORREL('Startup Gradients'!B5:B9,'Startup Gradients'!E6:E10),"") -> -0.23359334 | G41: =IFERROR(CORREL('Startup Gradients'!B5:B8,'Startup Gradients'!E7:E10),"") -> 0.64966742 | H41: =IFERROR(CORREL('Startup Gradients'!B5:B7,'Startup Gradients'!E8:E10),"") -> 0.99798271 | I41: =IF(OR(D41<7,COUNT(E41:H41)<4),"INSUFFICIENT",IF(ABS(E41)>=MAX(ABS(F41),ABS(G41),ABS(H41)),"0 h bin","ambiguous")) -> INSUFFICIENT
...

Sheet Route Parameters
A1: Normal-process packet transport routes
A2: Effective inventory is formula-derived from design flow and the reduced-order 20 s anchor.
A4: Route | B4: Source | C4: Destination | D4: Design flow kg/h | E4: Design dead time s | F4: Effective inventory kg | G4: Maximum dead time s | H4: Trend bound s | I4: Bound check
A5: 322E001_TO_323C003 | B5: 322E001 | C5: 323C003 | D5: 130482 | E5: 20 | F5: =D5*E5/3600 -> 724.9 | G5: 1800 | H5: 3600 | I5: =IF(E5<H5,"PASS","FAIL") -> PASS
A6: 323C003_TO_323F004 | B6: 323C003 | C6: 323F004 | D6: 105918.82 | E6: 20 | F6: =D6*E6/3600 -> 588.43792 | G6: 1800 | H6: 3600 | I6: =IF(E6<H6,"PASS","FAIL") -> PASS
A7: 323F004_TO_323F010 | B7: 323F004 | C7: 323F010 | D7: 101492.22 | E7: 20 | F7: =D7*E7/3600 -> 563.84565 | G7: 1800 | H7: 3600 | I7: =IF(E7<H7,"PASS","FAIL") -> PASS
A8: 323F010_TO_323D002 | B8: 323F010 | C8: 323D002 | D8: 92748.918 | E8: 20 | F8: =D8*E8/3600 -> 515.27177 | G8: 1800 | H8: 3600 | I8: =IF(E8<H8,"PASS","FAIL") -> PASS
A9: 323D002_TO_324E001 | B9: 323D002 | C9: 324E001 | D9: 92748.918 | E9: 20 | F9: =D9*E9/3600 -> 515.27177 | G9: 1800 | H9: 3600 | I9: =IF(E9<H9,"PASS","FAIL") -> PASS
